Workbook

Sheet Start Here
A1: Sitemap Generator — New Setup Template
A3: This workbook is a blank starting point for setting up the sitemap system for a new set of websites. It is pre-filled with a worked example (3 example domains + a handful of pages and languages) so the formula pattern is easy to copy.
A5: IMPORTANT — this file must be edited in Google Sheets, not directly in Excel.
A6: The 'SEO Planner' and 'Alternate Links Setup' tabs use Google Sheets-only functions (FILTER, REGEXEXTRACT, and Google's automatic range-spilling). These will not calculate correctly if you edit this .xlsx file directly in Microsoft Excel — formulas will show blank or error results. Before doing anything else:
A7: 1. Upload this file to Google Drive.
A8: 2. Right-click it → Open with → Google Sheets (this converts it into a native Google Sheet).
A9: 3. Do all further editing in that Google Sheet — it becomes your new master file.
A11: Full step-by-step setup instructions are in the accompanying file: SITEMAP_SETUP_GUIDE.md
A13: Tabs in this workbook:
A14: • Alternate Links Setup — define every language/region combination your sites will support.
A15: • SEO Planner — the working sheet where page URLs are entered; this is what gets exported to CSV.
A16: • Config — reference list of every language and country code (ISO/hreflang). Reusable as-is, no edits usually needed.
... A23: Replace the example values with your own real domains, pages and languages, then delete rows/columns you don't need. Delete this 'Start Here' tab once your setup is complete — it isn't read by the Python script.

Sheet SEO Planner
B1: example-com | C1: example-co-nz | D1: example-es
A2: Page | B2: =IFERROR(__xludf.DUMMYFUNCTION("ARRAYFORMULA(TOROW(FILTER('Alternate Links Setup'!B2:B60,'Alternate Links Setup'!B2:B60<>"""")&"" | ""&FILTER('Alternate Links Setup'!C2:C60,'Alternate Links Setup'!C2:C60<>"""")))"),"English | Australia") -> English | Australia | C2: =IFERROR(__xludf.DUMMYFUNCTION("""COMPUTED_VALUE"""),"English | New Zealand") -> English | New Zealand | D2: =IFERROR(__xludf.DUMMYFUNCTION("""COMPUTED_VALUE"""),"Spanish; Castilian | No region specified") -> Spanish; Castilian | No region specified | E2: =IFERROR(__xludf.DUMMYFUNCTION("""COMPUTED_VALUE"""),"English | United Kingdom") -> English | United Kingdom | F2: =IFERROR(__xludf.DUMMYFUNCTION("""COMPUTED_VALUE"""),"English | Canada") -> English | Canada | G2: =IFERROR(__xludf.DUMMYFUNCTION("""COMPUTED_VALUE"""),"English | United States of America") -> English | United States of America
B3: {=TOROW('Alternate Links Setup'!D2:D60)} -> en-AU | C3: en-NZ | D3: es | E3: en-GB | F3: en-CA | G3: en-US
A4: Home | B4: https://www.example.com/ | C4: https://www.example.co.nz/ | D4: https://www.example.es/ | E4: =IFERROR(__xludf.DUMMYFUNCTION("IFERROR(INDIRECT(ADDRESS(4,MATCH(VLOOKUP(E3,'Alternate Links Setup'!$D:$E,2,FALSE),$4:$4,0),1)&"":""&REGEXEXTRACT(ADDRESS(4,MATCH(VLOOKUP(E3,'Alternate Links Setup'!$D:$E,2,FALSE),$4:$4,0),1),""[A-Z]+"")),"""")"),"https://www.example.com/") -> https://www.example.com/ | F4: =IFERROR(__xludf.DUMMYFUNCTION("IFERROR(INDIRECT(ADDRESS(4,MATCH(VLOOKUP(F3,'Alternate Links Setup'!$D:$E,2,FALSE),$4:$4,0),1)&"":""&REGEXEXTRACT(ADDRESS(4,MATCH(VLOOKUP(F3,'Alternate Links Setup'!$D:$E,2,FALSE),$4:$4,0),1),""[A-Z]+"")),"""")"),"https://www.example.com/") -> https://www.example.com/ | G4: =IFERROR(__xludf.DUMMYFUNCTION("IFERROR(INDIRECT(ADDRESS(4,MATCH(VLOOKUP(G3,'Alternate Links Setup'!$D:$E,2,FALSE),$4:$4,0),1)&"":""&REGEXEXTRACT(ADDRESS(4,MATCH(VLOOKUP(G3,'Alternate Links Setup'!$D:$E,2,FALSE),$4:$4,0),1),""[A-Z]+"")),"""")"),"https://www.example.com/") -> https://www.example.com/
A5: About Us | B5: https://www.example.com/about-us | C5: https://www.example.co.nz/about-us | D5: https://www.example.es/sobre-nosotros | E5: =IFERROR(__xludf.DUMMYFUNCTION("""COMPUTED_VALUE"""),"https://www.example.com/about-us") -> https://www.example.com/about-us | F5: =IFERROR(__xludf.DUMMYFUNCTION("""COMPUTED_VALUE"""),"https://www.example.com/about-us") -> https://www.example.com/about-us | G5: =IFERROR(__xludf.DUMMYFUNCTION("""COMPUTED_VALUE"""),"https://www.example.com/about-us") -> https://www.example.com/about-us
A6: Contact Us | B6: https://www.example.com/contact-us | C6: https://www.example.co.nz/contact-us | D6: https://www.example.es/contacto | E6: =IFERROR(__xludf.DUMMYFUNCTION("""COMPUTED_VALUE"""),"https://www.example.com/contact-us") -> https://www.example.com/contact-us | F6: =IFERROR(__xludf.DUMMYFUNCTION("""COMPUTED_VALUE"""),"https://www.example.com/contact-us") -> https://www.example.com/contact-us | G6: =IFERROR(__xludf.DUMMYFUNCTION("""COMPUTED_VALUE"""),"https://www.example.com/contact-us") -> https://www.example.com/contact-us
A7: Blog | B7: https://www.example.com/blog | D7: https://www.example.es/blog | E7: =IFERROR(__xludf.DUMMYFUNCTION("""COMPUTED_VALUE"""),"https://www.example.com/blog") -> https://www.example.com/blog | F7: =IFERROR(__xludf.DUMMYFUNCTION("""COMPUTED_VALUE"""),"https://www.example.com/blog") -> https://www.example.com/blog | G7: =IFERROR(__xludf.DUMMYFUNCTION("""COMPUTED_VALUE"""),"https://www.example.com/blog") -> https://www.example.com/blog
A8: Site Map | B8: https://www.example.com/site-map | C8: https://www.example.co.nz/site-map | D8: https://www.example.es/mapa-del-sitio | E8: =IFERROR(__xludf.DUMMYFUNCTION("""COMPUTED_VALUE"""),"https://www.example.com/site-map") -> https://www.example.com/site-map | F8: =IFERROR(__xludf.DUMMYFUNCTION("""COMPUTED_VALUE"""),"https://www.example.com/site-map") -> https://www.example.com/site-map | G8: =IFERROR(__xludf.DUMMYFUNCTION("""COMPUTED_VALUE"""),"https://www.example.com/site-map") -> https://www.example.com/site-map

Sheet Alternate Links Setup
B1: Language | C1: Region | D1: Code | E1: Homepage
A2: ="Alt. language-locale #" & (ROW(A2) - 1) & ":" -> Alt. language-locale #1: | B2: English | C2: Australia | D2: =IFERROR(VLOOKUP($B$2:$B60,Config!A:B,2,0)&IF(OR($C$2:$C60="No region specified",$C$2:$C60=""),"","-"&VLOOKUP($C$2:$C60,Config!C:D,2,0)),"") -> en-AU | E2: https://www.example.com/
A3: ="Alt. language-locale #" & (ROW(A3) - 1) & ":" -> Alt. language-locale #2: | B3: English | C3: New Zealand | D3: =IFERROR(VLOOKUP($B$2:$B60,Config!A:B,2,0)&IF(OR($C$2:$C60="No region specified",$C$2:$C60=""),"","-"&VLOOKUP($C$2:$C60,Config!C:D,2,0)),"") -> en-NZ | E3: https://www.example.co.nz/
A4: ="Alt. language-locale #" & (ROW(A4) - 1) & ":" -> Alt. language-locale #3: | B4: Spanish; Castilian | C4: No region specified | D4: =IFERROR(VLOOKUP($B$2:$B60,Config!A:B,2,0)&IF(OR($C$2:$C60="No region specified",$C$2:$C60=""),"","-"&VLOOKUP($C$2:$C60,Config!C:D,2,0)),"") -> es | E4: https://www.example.es/
A5: ="Alt. language-locale #" & (ROW(A5) - 1) & ":" -> Alt. language-locale #4: | B5: English | C5: United Kingdom | D5: =IFERROR(VLOOKUP($B$2:$B60,Config!A:B,2,0)&IF(OR($C$2:$C60="No region specified",$C$2:$C60=""),"","-"&VLOOKUP($C$2:$C60,Config!C:D,2,0)),"") -> en-GB | E5: https://www.example.com/
A6: ="Alt. language-locale #" & (ROW(A6) - 1) & ":" -> Alt. language-locale #5: | B6: English | C6: Canada | D6: =IFERROR(VLOOKUP($B$2:$B60,Config!A:B,2,0)&IF(OR($C$2:$C60="No region specified",$C$2:$C60=""),"","-"&VLOOKUP($C$2:$C60,Config!C:D,2,0)),"") -> en-CA | E6: https://www.example.com/
A7: ="Alt. language-locale #" & (ROW(A7) - 1) & ":" -> Alt. language-locale #6: | B7: English | C7: United States of America | D7: =IFERROR(VLOOKUP($B$2:$B60,Config!A:B,2,0)&IF(OR($C$2:$C60="No region specified",$C$2:$C60=""),"","-"&VLOOKUP($C$2:$C60,Config!C:D,2,0)),"") -> en-US | E7: https://www.example.com/
A8: ="Alt. language-locale #" & (ROW(A8) - 1) & ":" -> Alt. language-locale #7: | D8: =IFERROR(VLOOKUP($B$2:$B60,Config!A:B,2,0)&IF(OR($C$2:$C60="No region specified",$C$2:$C60=""),"","-"&VLOOKUP($C$2:$C60,Config!C:D,2,0)),"")
A9: ="Alt. language-locale #" & (ROW(A9) - 1) & ":" -> Alt. language-locale #8: | D9: =IFERROR(VLOOKUP($B$2:$B60,Config!A:B,2,0)&IF(OR($C$2:$C60="No region specified",$C$2:$C60=""),"","-"&VLOOKUP($C$2:$C60,Config!C:D,2,0)),"")
A10: ="Alt. language-locale #" & (ROW(A10) - 1) & ":" -> Alt. language-locale #9: | D10: =IFERROR(VLOOKUP($B$2:$B60,Config!A:B,2,0)&IF(OR($C$2:$C60="No region specified",$C$2:$C60=""),"","-"&VLOOKUP($C$2:$C60,Config!C:D,2,0)),"")
A11: ="Alt. language-locale #" & (ROW(A11) - 1) & ":" -> Alt. language-locale #10: | D11: =IFERROR(VLOOKUP($B$2:$B60,Config!A:B,2,0)&IF(OR($C$2:$C60="No region specified",$C$2:$C60=""),"","-"&VLOOKUP($C$2:$C60,Config!C:D,2,0)),"")
A12: ="Alt. language-locale #" & (ROW(A12) - 1) & ":" -> Alt. language-locale #11: | D12: =IFERROR(VLOOKUP($B$2:$B60,Config!A:B,2,0)&IF(OR($C$2:$C60="No region specified",$C$2:$C60=""),"","-"&VLOOKUP($C$2:$C60,Config!C:D,2,0)),"")
A13: ="Alt. language-locale #" & (ROW(A13) - 1) & ":" -> Alt. language-locale #12: | D13: =IFERROR(VLOOKUP($B$2:$B60,Config!A:B,2,0)&IF(OR($C$2:$C60="No region specified",$C$2:$C60=""),"","-"&VLOOKUP($C$2:$C60,Config!C:D,2,0)),"")
A14: ="Alt. language-locale #" & (ROW(A14) - 1) & ":" -> Alt. language-locale #13: | D14: =IFERROR(VLOOKUP($B$2:$B60,Config!A:B,2,0)&IF(OR($C$2:$C60="No region specified",$C$2:$C60=""),"","-"&VLOOKUP($C$2:$C60,Config!C:D,2,0)),"")
A15: ="Alt. language-locale #" & (ROW(A15) - 1) & ":" -> Alt. language-locale #14: | D15: =IFERROR(VLOOKUP($B$2:$B60,Config!A:B,2,0)&IF(OR($C$2:$C60="No region specified",$C$2:$C60=""),"","-"&VLOOKUP($C$2:$C60,Config!C:D,2,0)),"")
A16: ="Alt. language-locale #" & (ROW(A16) - 1) & ":" -> Alt. language-locale #15: | D16: =IFERROR(VLOOKUP($B$2:$B60,Config!A:B,2,0)&IF(OR($C$2:$C60="No region specified",$C$2:$C60=""),"","-"&VLOOKUP($C$2:$C60,Config!C:D,2,0)),"")
A17: ="Alt. language-locale #" & (ROW(A17) - 1) & ":" -> Alt. language-locale #16: | D17: =IFERROR(VLOOKUP($B$2:$B60,Config!A:B,2,0)&IF(OR($C$2:$C60="No region specified",$C$2:$C60=""),"","-"&VLOOKUP($C$2:$C60,Config!C:D,2,0)),"")
A18: ="Alt. language-locale #" & (ROW(A18) - 1) & ":" -> Alt. language-locale #17: | D18: =IFERROR(VLOOKUP($B$2:$B60,Config!A:B,2,0)&IF(OR($C$2:$C60="No region specified",$C$2:$C60=""),"","-"&VLOOKUP($C$2:$C60,Config!C:D,2,0)),"")
A19: ="Alt. language-locale #" & (ROW(A19) - 1) & ":" -> Alt. language-locale #18: | D19: =IFERROR(VLOOKUP($B$2:$B60,Config!A:B,2,0)&IF(OR($C$2:$C60="No region specified",$C$2:$C60=""),"","-"&VLOOKUP($C$2:$C60,Config!C:D,2,0)),"")
A20: ="Alt. language-locale #" & (ROW(A20) - 1) & ":" -> Alt. language-locale #19: | D20: =IFERROR(VLOOKUP($B$2:$B60,Config!A:B,2,0)&IF(OR($C$2:$C60="No region specified",$C$2:$C60=""),"","-"&VLOOKUP($C$2:$C60,Config!C:D,2,0)),"")
A21: ="Alt. language-locale #" & (ROW(A21) - 1) & ":" -> Alt. language-locale #20: | D21: =IFERROR(VLOOKUP($B$2:$B60,Config!A:B,2,0)&IF(OR($C$2:$C60="No region specified",$C$2:$C60=""),"","-"&VLOOKUP($C$2:$C60,Config!C:D,2,0)),"")
A22: ="Alt. language-locale #" & (ROW(A22) - 1) & ":" -> Alt. language-locale #21: | D22: =IFERROR(VLOOKUP($B$2:$B60,Config!A:B,2,0)&IF(OR($C$2:$C60="No region specified",$C$2:$C60=""),"","-"&VLOOKUP($C$2:$C60,Config!C:D,2,0)),"")
A23: ="Alt. language-locale #" & (ROW(A23) - 1) & ":" -> Alt. language-locale #22: | D23: =IFERROR(VLOOKUP($B$2:$B60,Config!A:B,2,0)&IF(OR($C$2:$C60="No region specified",$C$2:$C60=""),"","-"&VLOOKUP($C$2:$C60,Config!C:D,2,0)),"")
A24: ="Alt. language-locale #" & (ROW(A24) - 1) & ":" -> Alt. language-locale #23: | D24: =IFERROR(VLOOKUP($B$2:$B60,Config!A:B,2,0)&IF(OR($C$2:$C60="No region specified",$C$2:$C60=""),"","-"&VLOOKUP($C$2:$C60,Config!C:D,2,0)),"")
A25: ="Alt. language-locale #" & (ROW(A25) - 1) & ":" -> Alt. language-locale #24: | D25: =IFERROR(VLOOKUP($B$2:$B60,Config!A:B,2,0)&IF(OR($C$2:$C60="No region specified",$C$2:$C60=""),"","-"&VLOOKUP($C$2:$C60,Config!C:D,2,0)),"")
A26: ="Alt. language-locale #" & (ROW(A26) - 1) & ":" -> Alt. language-locale #25: | D26: =IFERROR(VLOOKUP($B$2:$B60,Config!A:B,2,0)&IF(OR($C$2:$C60="No region specified",$C$2:$C60=""),"","-"&VLOOKUP($C$2:$C60,Config!C:D,2,0)),"")
A27: ="Alt. language-locale #" & (ROW(A27) - 1) & ":" -> Alt. language-locale #26: | D27: =IFERROR(VLOOKUP($B$2:$B60,Config!A:B,2,0)&IF(OR($C$2:$C60="No region specified",$C$2:$C60=""),"","-"&VLOOKUP($C$2:$C60,Config!C:D,2,0)),"")
A28: ="Alt. language-locale #" & (ROW(A28) - 1) & ":" -> Alt. language-locale #27: | D28: =IFERROR(VLOOKUP($B$2:$B60,Config!A:B,2,0)&IF(OR($C$2:$C60="No region specified",$C$2:$C60=""),"","-"&VLOOKUP($C$2:$C60,Config!C:D,2,0)),"")
A29: ="Alt. language-locale #" & (ROW(A29) - 1) & ":" -> Alt. language-locale #28: | D29: =IFERROR(VLOOKUP($B$2:$B60,Config!A:B,2,0)&IF(OR($C$2:$C60="No region specified",$C$2:$C60=""),"","-"&VLOOKUP($C$2:$C60,Config!C:D,2,0)),"")
A30: ="Alt. language-locale #" & (ROW(A30) - 1) & ":" -> Alt. language-locale #29: | D30: =IFERROR(VLOOKUP($B$2:$B60,Config!A:B,2,0)&IF(OR($C$2:$C60="No region specified",$C$2:$C60=""),"","-"&VLOOKUP($C$2:$C60,Config!C:D,2,0)),"")
A31: ="Alt. language-locale #" & (ROW(A31) - 1) & ":" -> Alt. language-locale #30: | D31: =IFERROR(VLOOKUP($B$2:$B60,Config!A:B,2,0)&IF(OR($C$2:$C60="No region specified",$C$2:$C60=""),"","-"&VLOOKUP($C$2:$C60,Config!C:D,2,0)),"")
A32: ="Alt. language-locale #" & (ROW(A32) - 1) & ":" -> Alt. language-locale #31: | D32: =IFERROR(VLOOKUP($B$2:$B60,Config!A:B,2,0)&IF(OR($C$2:$C60="No region specified",$C$2:$C60=""),"","-"&VLOOKUP($C$2:$C60,Config!C:D,2,0)),"")
A33: ="Alt. language-locale #" & (ROW(A33) - 1) & ":" -> Alt. language-locale #32: | D33: =IFERROR(VLOOKUP($B$2:$B60,Config!A:B,2,0)&IF(OR($C$2:$C60="No region specified",$C$2:$C60=""),"","-"&VLOOKUP($C$2:$C60,Config!C:D,2,0)),"")
A34: ="Alt. language-locale #" & (ROW(A34) - 1) & ":" -> Alt. language-locale #33: | D34: =IFERROR(VLOOKUP($B$2:$B60,Config!A:B,2,0)&IF(OR($C$2:$C60="No region specified",$C$2:$C60=""),"","-"&VLOOKUP($C$2:$C60,Config!C:D,2,0)),"")
A35: ="Alt. language-locale #" & (ROW(A35) - 1) & ":" -> Alt. language-locale #34: | D35: =IFERROR(VLOOKUP($B$2:$B60,Config!A:B,2,0)&IF(OR($C$2:$C60="No region specified",$C$2:$C60=""),"","-"&VLOOKUP($C$2:$C60,Config!C:D,2,0)),"")
A36: ="Alt. language-locale #" & (ROW(A36) - 1) & ":" -> Alt. language-locale #35: | D36: =IFERROR(VLOOKUP($B$2:$B60,Config!A:B,2,0)&IF(OR($C$2:$C60="No region specified",$C$2:$C60=""),"","-"&VLOOKUP($C$2:$C60,Config!C:D,2,0)),"")
A37: ="Alt. language-locale #" & (ROW(A37) - 1) & ":" -> Alt. language-locale #36: | D37: =IFERROR(VLOOKUP($B$2:$B60,Config!A:B,2,0)&IF(OR($C$2:$C60="No region specified",$C$2:$C60=""),"","-"&VLOOKUP($C$2:$C60,Config!C:D,2,0)),"")
A38: ="Alt. language-locale #" & (ROW(A38) - 1) & ":" -> Alt. language-locale #37: | D38: =IFERROR(VLOOKUP($B$2:$B60,Config!A:B,2,0)&IF(OR($C$2:$C60="No region specified",$C$2:$C60=""),"","-"&VLOOKUP($C$2:$C60,Config!C:D,2,0)),"")
A39: ="Alt. language-locale #" & (ROW(A39) - 1) & ":" -> Alt. language-locale #38: | D39: =IFERROR(VLOOKUP($B$2:$B60,Config!A:B,2,0)&IF(OR($C$2:$C60="No region specified",$C$2:$C60=""),"","-"&VLOOKUP($C$2:$C60,Config!C:D,2,0)),"")
A40: ="Alt. language-locale #" & (ROW(A40) - 1) & ":" -> Alt. language-locale #39: | D40: =IFERROR(VLOOKUP($B$2:$B60,Config!A:B,2,0)&IF(OR($C$2:$C60="No region specified",$C$2:$C60=""),"","-"&VLOOKUP($C$2:$C60,Config!C:D,2,0)),"")
...

Sheet Config
A1: Language | B1: Code | C1: Country | D1: Code
A2: Global | B2: x-default | C2: No region specified
A3: Abkhazian | B3: ab | C3: Afghanistan | D3: AF
A4: Afar | B4: aa | C4: Aland Islands | D4: AX
A5: Afrikaans | B5: af | C5: Albania | D5: AL
A6: Albanian | B6: sq | C6: Algeria | D6: DZ
A7: Amharic | B7: am | C7: American Samoa | D7: AS
A8: Arabic | B8: ar | C8: Andorra | D8: AD
A9: Aragonese | B9: an | C9: Angola | D9: AO
A10: Armenian | B10: hy | C10: Anguilla | D10: AI
A11: Assamese | B11: as | C11: Antarctica | D11: AQ
A12: Avestan | B12: ae | C12: Antigua and Barbuda | D12: AG
A13: Aymara | B13: ay | C13: Argentina | D13: AR
A14: Azerbaijani | B14: az | C14: Armenia | D14: AM
... A174: Zulu | B174: zu | C174: Palau | D174: PW
C175: Palestinian Territory | D175: PS
C176: Panama | D176: PA
C177: Papua New Guinea | D177: PG
C178: Paraguay | D178: PY
C179: Peru | D179: PE
C180: Philippines | D180: PH
C181: Pitcairn | D181: PN
C182: Poland | D182: PL
C183: Portugal | D183: PT
C184: Puerto Rico | D184: PR
C185: Qatar | D185: QA
C186: Réunion | D186: RE
... C253: Zimbabwe | D253: ZW
